Workbook
Name Bold: 'Değişkenler'!$C$12
Name criteria1: #REF!
Name criteria1: [1]'Değişkenler'!$D$49:$D$52
Name criteria1: 'Değişkenler'!$D$49:$D$52
Name criteria2: 'Değişkenler'!$E$49:$E$53
Name criteriaAP: 'Değişkenler'!$F$49:$F$50
Name CriteriaAP2: #REF!
Name CriteriaAP2: #REF!
Name CriteriaAP2: 'Aksiyon Planı'!$Q$2:$Q$3
Name extraTest: #REF!
Name extraTest: 'Denetim'!$E$2
Name IDAudit: 'TabletParametreleri'!$B$1
Name maxMPA: 'Değişkenler'!$B$26
Name minMPA: 'Değişkenler'!$B$25
Name NSAmaxC: 'Değişkenler'!$B$24
Name NSAmaxS: 'Değişkenler'!$B$22
Name NSAminC: 'Değişkenler'!$B$23
Name NSAminS: 'Değişkenler'!$B$21
Name or: [2]'Değişkenler'!$D$49:$D$52
Name Safety: 'Değişkenler'!$C$17
Name TestAudit: [3]'Değişkenler'!$I$50
Name TestAudit: 'Değişkenler'!$I$50
Name Titre_Audit: #REF!
Name Titre_Audit: 'Özet'!$C$1
Name Titre_PPQ: #REF!
Name Titre_PPQ: #REF!
Name Type_Audit: #REF!
Name Type_Audit: 'Özet'!$P$1
Name Type_PPQ: #REF!
Name Type_PPQ: #REF!
Name TypeAudit: 'TabletParametreleri'!$B$2
Name value1: #REF!
Name value1: 'Değişkenler'!$B$49:$B$55
Name value2: 'Değişkenler'!$C$49:$C$54
Name VersionAudit: 'TabletParametreleri'!$B$3

Sheet Kapak
A1: Referans: 01598_16_04265
A2: NSA - Yeni Tedarikçi Değerlendirmesi ==> SAMT No:
A3: Tedarikçi Tesis Bilgileri
A4: Tedarikçi Adı | B4: EKOL GLASS CAM SANAYİ VE TİCARET LİMİTED ŞİRKETİ
A5: Tedarikçi Adresi | B5: Vakıf Mahallesi, 9. Turan Sokak No: 1/A, Yıldırım/Bursa, Türkiye
A6: Tedarikçi DUNS / COFOR / IATF | B6: COFOR - A02K2H 01
A7: IATF numarası: | B7: -
A8: Tedarikçi Öz Değerlendirmesi
A9: Öz Değerlendirme Tarihi | B9: 20.10.2026
A10: Tedarikçi İrtibat Kişisi | B10: Batuhan Şengül
A11: E-posta ve telefon numarası | B11: batuhan.sengul@ekolglass.com / +90 545 921 28 32
A12: Yerinde Müşteri Değerlendirmesi
A13: Denetim Tarihi
A14: Denetçi Adı
A15: E-posta ve Telefon Numarası
A16: Denetimin Kapsamı
A17: Fiat Tris Sol ve Sağ Yan Kapı Sürgülü Camları

Sheet KİLİT
A1: Kilit | B1: Kapalı | D1: Kapak
A2: Yönetici | B2: Kapalı | D2: KİLİT
A3: Oluşturuldu | B3: EVET | D3: PCPA Özeti
D4: Özet
D5: Denetim
D6: Yorum Türü
D7: Aksiyon Planı
D8: Talimat ve Eğitim
D9: Aksiyon Planı Talimatı
D10: QSB+ Talimatı
D11: NSA Talimatı
D12: PCPA Talimatı
D13: Terimler Sözlüğü
D14: paramTablette
D15: Variable
D16: variableAudit

Sheet Özet
C1: NSA - Yeni Tedarikçi Değerlendirmesi | P1: GÜVENLİK
A2: Tedarikçi Adı | C2: ='Kapak'!B4 -> EKOL GLASS CAM SANAYİ VE TİCARET LİMİTED ŞİRKETİ | H2: Denetimin Kapsamı | P2: ='Kapak'!$A$17 -> Fiat Tris Sol ve Sağ Yan Kapı Sürgülü Camları
A3: Tedarikçi Adresi | C3: ='Kapak'!B5 -> Vakıf Mahallesi, 9. Turan Sokak No: 1/A, Yıldırım/Bursa, Türkiye | H3: Denetim Tarihi | P3: ='Kapak'!B13 -> 0
A4: Tedarikçi DUNS / COFOR | C4: ='Kapak'!B6 -> COFOR - A02K2H 01 | H4: Denetçi Adı | P4: ='Kapak'!B14 -> 0
A5: Önceki NSA Oranı | H5: Önceki NSA Rengi
D8: Öz Değerlendirme Puanlaması | H8: Müşteri Denetimi Puanlaması | L8: Aksiyon Planı Puanlaması
A9: Temel Unsurlar | D9: Potansiyel | E9: Toplam | F9: % | G9: Durum | H9: Potansiyel | I9: Toplam | J9: % | K9: Durum | L9: Potansiyel | M9: Toplam | N9: % | O9: Durum | P9: Yorum
A10: 1 | B10: Tesis Kurumsal Yönetimi | C10: CMP | D10: ='DenetimDeğişkenleri'!G10-'DenetimDeğişkenleri'!E10 -> 9 | E10: ='DenetimDeğişkenleri'!B10 -> 5 | F10: =IF('DenetimDeğişkenleri'!H10=0,'DenetimDeğişkenleri'!B10/('DenetimDeğişkenleri'!B10+'DenetimDeğişkenleri'!C10*Bold+'DenetimDeğişkenleri'!D10+'DenetimDeğişkenleri'!F10+'DenetimDeğişkenleri'!X10),"NR") -> 0.45454545 | G10: =IF('DenetimDeğişkenleri'!$X$10=0,IF(F10<>"NR",IF(Safety=1,IF(F10<0.9,IF(F10<0.7,"R","Y"),"G"),IF(F10<0.8,IF(F10<0.6,"R","Y"),"G")),"NR"),"R") -> R | H10: ='DenetimDeğişkenleri'!N10-'DenetimDeğişkenleri'!L10 -> 9 | I10: ='DenetimDeğişkenleri'!I10 -> 0 | J10: =IF('DenetimDeğişkenleri'!O10=0,'DenetimDeğişkenleri'!I10/('DenetimDeğişkenleri'!I10+'DenetimDeğişkenleri'!J10*Bold+'DenetimDeğişkenleri'!K10+'DenetimDeğişkenleri'!M10+'DenetimDeğişkenleri'!Y10),"NR") -> NR | K10: =IF('DenetimDeğişkenleri'!$Y$10=0,IF(J10<>"NR",IF(Safety=1,IF(J10<0.9,IF(J10<0.7,"R","Y"),"G"),IF(J10<0.8,IF(J10<0.6,"R","Y"),"G")),"NR"),"R") -> NR | L10: ='DenetimDeğişkenleri'!U10-'DenetimDeğişkenleri'!S10 -> 9 | M10: ='DenetimDeğişkenleri'!P10 -> 0 | N10: =IF('DenetimDeğişkenleri'!V10=0,'DenetimDeğişkenleri'!P10/('DenetimDeğişkenleri'!P10+'DenetimDeğişkenleri'!Q10*Bold+'DenetimDeğişkenleri'!R10+'DenetimDeğişkenleri'!T10+'DenetimDeğişkenleri'!Z10),"NR") -> NR | O10: =IF('DenetimDeğişkenleri'!$Z$10=0,IF(N10<>"NR",IF(Safety=1,IF(N10<0.9,IF(N10<0.7,"R","Y"),"G"),IF(N10<0.8,IF(N10<0.6,"R","Y"),"G")),"NR"),"R") -> NR
A11: 2 | B11: Grup Kurumsal Yönetimi | C11: CMG | D11: ='DenetimDeğişkenleri'!G11-'DenetimDeğişkenleri'!E11 -> 9 | E11: ='DenetimDeğişkenleri'!B11 -> 4 | F11: =IF('DenetimDeğişkenleri'!H11=0,'DenetimDeğişkenleri'!B11/('DenetimDeğişkenleri'!B11+'DenetimDeğişkenleri'!C11*Bold+'DenetimDeğişkenleri'!D11+'DenetimDeğişkenleri'!F11+'DenetimDeğişkenleri'!X11),"NR") -> 0.36363636 | G11: =IF('DenetimDeğişkenleri'!$X$11=0,IF(F11<>"NR",IF(Safety=1,IF(F11<0.9,IF(F11<0.7,"R","Y"),"G"),IF(F11<0.8,IF(F11<0.6,"R","Y"),"G")),"NR"),"R") -> R | H11: ='DenetimDeğişkenleri'!N11-'DenetimDeğişkenleri'!L11 -> 9 | I11: ='DenetimDeğişkenleri'!I11 -> 0 | J11: =IF('DenetimDeğişkenleri'!O11=0,'DenetimDeğişkenleri'!I11/('DenetimDeğişkenleri'!I11+'DenetimDeğişkenleri'!J11*Bold+'DenetimDeğişkenleri'!K11+'DenetimDeğişkenleri'!M11+'DenetimDeğişkenleri'!Y11),"NR") -> NR | K11: =IF('DenetimDeğişkenleri'!$Y$11=0,IF(J11<>"NR",IF(Safety=1,IF(J11<0.9,IF(J11<0.7,"R","Y"),"G"),IF(J11<0.8,IF(J11<0.6,"R","Y"),"G")),"NR"),"R") -> NR | L11: ='DenetimDeğişkenleri'!U11-'DenetimDeğişkenleri'!S11 -> 9 | M11: ='DenetimDeğişkenleri'!P11 -> 0 | N11: =IF('DenetimDeğişkenleri'!V11=0,'DenetimDeğişkenleri'!P11/('DenetimDeğişkenleri'!P11+'DenetimDeğişkenleri'!Q11*Bold+'DenetimDeğişkenleri'!R11+'DenetimDeğişkenleri'!T11+'DenetimDeğişkenleri'!Z11),"NR") -> NR | O11: =IF('DenetimDeğişkenleri'!$Z$11=0,IF(N11<>"NR",IF(Safety=1,IF(N11<0.9,IF(N11<0.7,"R","Y"),"G"),IF(N11<0.8,IF(N11<0.6,"R","Y"),"G")),"NR"),"R") -> NR
A12: 3 | B12: Hızlı Müdahale | C12: FR | D12: ='DenetimDeğişkenleri'!G12-'DenetimDeğişkenleri'!E12 -> 9 | E12: ='DenetimDeğişkenleri'!B12 -> 9 | F12: =IF('DenetimDeğişkenleri'!H12=0,'DenetimDeğişkenleri'!B12/('DenetimDeğişkenleri'!B12+'DenetimDeğişkenleri'!C12*Bold+'DenetimDeğişkenleri'!D12+'DenetimDeğişkenleri'!F12+'DenetimDeğişkenleri'!X12),"NR") -> 1 | G12: =IF('DenetimDeğişkenleri'!$X$12=0,IF(F12<>"NR",IF(Safety=1,IF(F12<0.9,IF(F12<0.7,"R","Y"),"G"),IF(F12<0.8,IF(F12<0.6,"R","Y"),"G")),"NR"),"R") -> G | H12: ='DenetimDeğişkenleri'!N12-'DenetimDeğişkenleri'!L12 -> 9 | I12: ='DenetimDeğişkenleri'!I12 -> 0 | J12: =IF('DenetimDeğişkenleri'!O12=0,'DenetimDeğişkenleri'!I12/('DenetimDeğişkenleri'!I12+'DenetimDeğişkenleri'!J12*Bold+'DenetimDeğişkenleri'!K12+'DenetimDeğişkenleri'!M12+'DenetimDeğişkenleri'!Y12),"NR") -> NR | K12: =IF('DenetimDeğişkenleri'!$Y$12=0,IF(J12<>"NR",IF(Safety=1,IF(J12<0.9,IF(J12<0.7,"R","Y"),"G"),IF(J12<0.8,IF(J12<0.6,"R","Y"),"G")),"NR"),"R") -> NR | L12: ='DenetimDeğişkenleri'!U12-'DenetimDeğişkenleri'!S12 -> 9 | M12: ='DenetimDeğişkenleri'!P12 -> 0 | N12: =IF('DenetimDeğişkenleri'!V12=0,'DenetimDeğişkenleri'!P12/('DenetimDeğişkenleri'!P12+'DenetimDeğişkenleri'!Q12*Bold+'DenetimDeğişkenleri'!R12+'DenetimDeğişkenleri'!T12+'DenetimDeğişkenleri'!Z12),"NR") -> NR | O12: =IF('DenetimDeğişkenleri'!$Z$12=0,IF(N12<>"NR",IF(Safety=1,IF(N12<0.9,IF(N12<0.7,"R","Y"),"G"),IF(N12<0.8,IF(N12<0.6,"R","Y"),"G")),"NR"),"R") -> NR
A13: 4 | B13: Parça ve Proses Kontrolü | C13: PPC | D13: ='DenetimDeğişkenleri'!G13-'DenetimDeğişkenleri'!E13 -> 9 | E13: ='DenetimDeğişkenleri'!B13 -> 6 | F13: =IF('DenetimDeğişkenleri'!H13=0,'DenetimDeğişkenleri'!B13/('DenetimDeğişkenleri'!B13+'DenetimDeğişkenleri'!C13*Bold+'DenetimDeğişkenleri'!D13+'DenetimDeğişkenleri'!F13+'DenetimDeğişkenleri'!X13),"NR") -> 0.6 | G13: =IF('DenetimDeğişkenleri'!$X$13=0,IF(F13<>"NR",IF(Safety=1,IF(F13<0.9,IF(F13<0.7,"R","Y"),"G"),IF(F13<0.8,IF(F13<0.6,"R","Y"),"G")),"NR"),"R") -> R | H13: ='DenetimDeğişkenleri'!N13-'DenetimDeğişkenleri'!L13 -> 9 | I13: ='DenetimDeğişkenleri'!I13 -> 0 | J13: =IF('DenetimDeğişkenleri'!O13=0,'DenetimDeğişkenleri'!I13/('DenetimDeğişkenleri'!I13+'DenetimDeğişkenleri'!J13*Bold+'DenetimDeğişkenleri'!K13+'DenetimDeğişkenleri'!M13+'DenetimDeğişkenleri'!Y13),"NR") -> NR | K13: =IF('DenetimDeğişkenleri'!$Y$13=0,IF(J13<>"NR",IF(Safety=1,IF(J13<0.9,IF(J13<0.7,"R","Y"),"G"),IF(J13<0.8,IF(J13<0.6,"R","Y"),"G")),"NR"),"R") -> NR | L13: ='DenetimDeğişkenleri'!U13-'DenetimDeğişkenleri'!S13 -> 9 | M13: ='DenetimDeğişkenleri'!P13 -> 0 | N13: =IF('DenetimDeğişkenleri'!V13=0,'DenetimDeğişkenleri'!P13/('DenetimDeğişkenleri'!P13+'DenetimDeğişkenleri'!Q13*Bold+'DenetimDeğişkenleri'!R13+'DenetimDeğişkenleri'!T13+'DenetimDeğişkenleri'!Z13),"NR") -> NR | O13: =IF('DenetimDeğişkenleri'!$Z$13=0,IF(N13<>"NR",IF(Safety=1,IF(N13<0.9,IF(N13<0.7,"R","Y"),"G"),IF(N13<0.8,IF(N13<0.6,"R","Y"),"G")),"NR"),"R") -> NR
A14: 5 | B14: Üretim Başlangıcı ve Hata Önleme Yönetimi | C14: SP&EP | D14: ='DenetimDeğişkenleri'!G14-'DenetimDeğişkenleri'!E14 -> 9 | E14: ='DenetimDeğişkenleri'!B14 -> 7 | F14: =IF('DenetimDeğişkenleri'!H14=0,'DenetimDeğişkenleri'!B14/('DenetimDeğişkenleri'!B14+'DenetimDeğişkenleri'!C14*Bold+'DenetimDeğişkenleri'!D14+'DenetimDeğişkenleri'!F14+'DenetimDeğişkenleri'!X14),"NR") -> 0.63636364 | G14: =IF('DenetimDeğişkenleri'!$X$14=0,IF(F14<>"NR",IF(Safety=1,IF(F14<0.9,IF(F14<0.7,"R","Y"),"G"),IF(F14<0.8,IF(F14<0.6,"R","Y"),"G")),"NR"),"R") -> R | H14: ='DenetimDeğişkenleri'!N14-'DenetimDeğişkenleri'!L14 -> 9 | I14: ='DenetimDeğişkenleri'!I14 -> 0 | J14: =IF('DenetimDeğişkenleri'!O14=0,'DenetimDeğişkenleri'!I14/('DenetimDeğişkenleri'!I14+'DenetimDeğişkenleri'!J14*Bold+'DenetimDeğişkenleri'!K14+'DenetimDeğişkenleri'!M14+'DenetimDeğişkenleri'!Y14),"NR") -> NR | K14: =IF('DenetimDeğişkenleri'!$Y$14=0,IF(J14<>"NR",IF(Safety=1,IF(J14<0.9,IF(J14<0.7,"R","Y"),"G"),IF(J14<0.8,IF(J14<0.6,"R","Y"),"G")),"NR"),"R") -> NR | L14: ='DenetimDeğişkenleri'!U14-'DenetimDeğişkenleri'!S14 -> 9 | M14: ='DenetimDeğişkenleri'!P14 -> 0 | N14: =IF('DenetimDeğişkenleri'!V14=0,'DenetimDeğişkenleri'!P14/('DenetimDeğişkenleri'!P14+'DenetimDeğişkenleri'!Q14*Bold+'DenetimDeğişkenleri'!R14+'DenetimDeğişkenleri'!T14+'DenetimDeğişkenleri'!Z14),"NR") -> NR | O14: =IF('DenetimDeğişkenleri'!$Z$14=0,IF(N14<>"NR",IF(Safety=1,IF(N14<0.9,IF(N14<0.7,"R","Y"),"G"),IF(N14<0.8,IF(N14<0.6,"R","Y"),"G")),"NR"),"R") -> NR
A15: 6 | B15: Garanti Sorunlarının Yönetimi | C15: WIM | D15: ='DenetimDeğişkenleri'!G15-'DenetimDeğişkenleri'!E15 -> 6 | E15: ='DenetimDeğişkenleri'!B15 -> 4 | F15: =IF('DenetimDeğişkenleri'!H15=0,'DenetimDeğişkenleri'!B15/('DenetimDeğişkenleri'!B15+'DenetimDeğişkenleri'!C15*Bold+'DenetimDeğişkenleri'!D15+'DenetimDeğişkenleri'!F15+'DenetimDeğişkenleri'!X15),"NR") -> 0.57142857 | G15: =IF('DenetimDeğişkenleri'!$X$15=0,IF(F15<>"NR",IF(Safety=1,IF(F15<0.9,IF(F15<0.7,"R","Y"),"G"),IF(F15<0.8,IF(F15<0.6,"R","Y"),"G")),"NR"),"R") -> R | H15: ='DenetimDeğişkenleri'!N15-'DenetimDeğişkenleri'!L15 -> 6 | I15: ='DenetimDeğişkenleri'!I15 -> 0 | J15: =IF('DenetimDeğişkenleri'!O15=0,'DenetimDeğişkenleri'!I15/('DenetimDeğişkenleri'!I15+'DenetimDeğişkenleri'!J15*Bold+'DenetimDeğişkenleri'!K15+'DenetimDeğişkenleri'!M15+'DenetimDeğişkenleri'!Y15),"NR") -> NR | K15: =IF('DenetimDeğişkenleri'!$Y$15=0,IF(J15<>"NR",IF(Safety=1,IF(J15<0.9,IF(J15<0.7,"R","Y"),"G"),IF(J15<0.8,IF(J15<0.6,"R","Y"),"G")),"NR"),"R") -> NR | L15: ='DenetimDeğişkenleri'!U15-'DenetimDeğişkenleri'!S15 -> 6 | M15: ='DenetimDeğişkenleri'!P15 -> 0 | N15: =IF('DenetimDeğişkenleri'!V15=0,'DenetimDeğişkenleri'!P15/('DenetimDeğişkenleri'!P15+'DenetimDeğişkenleri'!Q15*Bold+'DenetimDeğişkenleri'!R15+'DenetimDeğişkenleri'!T15+'DenetimDeğişkenleri'!Z15),"NR") -> NR | O15: =IF('DenetimDeğişkenleri'!$Z$15=0,IF(N15<>"NR",IF(Safety=1,IF(N15<0.9,IF(N15<0.7,"R","Y"),"G"),IF(N15<0.8,IF(N15<0.6,"R","Y"),"G")),"NR"),"R") -> NR
A16: 7 | B16: Standartlaştırılmış İş | C16: SW | D16: ='DenetimDeğişkenleri'!G16-'DenetimDeğişkenleri'!E16 -> 9 | E16: ='DenetimDeğişkenleri'!B16 -> 8 | F16: =IF('DenetimDeğişkenleri'!H16=0,'DenetimDeğişkenleri'!B16/('DenetimDeğişkenleri'!B16+'DenetimDeğişkenleri'!C16*Bold+'DenetimDeğişkenleri'!D16+'DenetimDeğişkenleri'!F16+'DenetimDeğişkenleri'!X16),"NR") -> 0.8 | G16: =IF('DenetimDeğişkenleri'!$X$16=0,IF(F16<>"NR",IF(Safety=1,IF(F16<0.9,IF(F16<0.7,"R","Y"),"G"),IF(F16<0.8,IF(F16<0.6,"R","Y"),"G")),"NR"),"R") -> Y | H16: ='DenetimDeğişkenleri'!N16-'DenetimDeğişkenleri'!L16 -> 9 | I16: ='DenetimDeğişkenleri'!I16 -> 0 | J16: =IF('DenetimDeğişkenleri'!O16=0,'DenetimDeğişkenleri'!I16/('DenetimDeğişkenleri'!I16+'DenetimDeğişkenleri'!J16*Bold+'DenetimDeğişkenleri'!K16+'DenetimDeğişkenleri'!M16+'DenetimDeğişkenleri'!Y16),"NR") -> NR | K16: =IF('DenetimDeğişkenleri'!$Y$16=0,IF(J16<>"NR",IF(Safety=1,IF(J16<0.9,IF(J16<0.7,"R","Y"),"G"),IF(J16<0.8,IF(J16<0.6,"R","Y"),"G")),"NR"),"R") -> NR | L16: ='DenetimDeğişkenleri'!U16-'DenetimDeğişkenleri'!S16 -> 9 | M16: ='DenetimDeğişkenleri'!P16 -> 0 | N16: =IF('DenetimDeğişkenleri'!V16=0,'DenetimDeğişkenleri'!P16/('DenetimDeğişkenleri'!P16+'DenetimDeğişkenleri'!Q16*Bold+'DenetimDeğişkenleri'!R16+'DenetimDeğişkenleri'!T16+'DenetimDeğişkenleri'!Z16),"NR") -> NR | O16: =IF('DenetimDeğişkenleri'!$Z$16=0,IF(N16<>"NR",IF(Safety=1,IF(N16<0.9,IF(N16<0.7,"R","Y"),"G"),IF(N16<0.8,IF(N16<0.6,"R","Y"),"G")),"NR"),"R") -> NR
A17: 8 | B17: Risk Azaltma | C17: RR | D17: ='DenetimDeğişkenleri'!G17-'DenetimDeğişkenleri'!E17 -> 9 | E17: ='DenetimDeğişkenleri'!B17 -> 7 | F17: =IF('DenetimDeğişkenleri'!H17=0,'DenetimDeğişkenleri'!B17/('DenetimDeğişkenleri'!B17+'DenetimDeğişkenleri'!C17*Bold+'DenetimDeğişkenleri'!D17+'DenetimDeğişkenleri'!F17+'DenetimDeğişkenleri'!X17),"NR") -> 0.7 | G17: =IF('DenetimDeğişkenleri'!$X$17=0,IF(F17<>"NR",IF(Safety=1,IF(F17<0.9,IF(F17<0.7,"R","Y"),"G"),IF(F17<0.8,IF(F17<0.6,"R","Y"),"G")),"NR"),"R") -> Y | H17: ='DenetimDeğişkenleri'!N17-'DenetimDeğişkenleri'!L17 -> 9 | I17: ='DenetimDeğişkenleri'!I17 -> 0 | J17: =IF('DenetimDeğişkenleri'!O17=0,'DenetimDeğişkenleri'!I17/('DenetimDeğişkenleri'!I17+'DenetimDeğişkenleri'!J17*Bold+'DenetimDeğişkenleri'!K17+'DenetimDeğişkenleri'!M17+'DenetimDeğişkenleri'!Y17),"NR") -> NR | K17: =IF('DenetimDeğişkenleri'!$Y$17=0,IF(J17<>"NR",IF(Safety=1,IF(J17<0.9,IF(J17<0.7,"R","Y"),"G"),IF(J17<0.8,IF(J17<0.6,"R","Y"),"G")),"NR"),"R") -> NR | L17: ='DenetimDeğişkenleri'!U17-'DenetimDeğişkenleri'!S17 -> 9 | M17: ='DenetimDeğişkenleri'!P17 -> 0 | N17: =IF('DenetimDeğişkenleri'!V17=0,'DenetimDeğişkenleri'!P17/('DenetimDeğişkenleri'!P17+'DenetimDeğişkenleri'!Q17*Bold+'DenetimDeğişkenleri'!R17+'DenetimDeğişkenleri'!T17+'DenetimDeğişkenleri'!Z17),"NR") -> NR | O17: =IF('DenetimDeğişkenleri'!$Z$17=0,IF(N17<>"NR",IF(Safety=1,IF(N17<0.9,IF(N17<0.7,"R","Y"),"G"),IF(N17<0.8,IF(N17<0.6,"R","Y"),"G")),"NR"),"R") -> NR
A18: 9 | B18: Değişiklik Yönetimi | C18: MC | D18: ='DenetimDeğişkenleri'!G18-'DenetimDeğişkenleri'!E18 -> 3 | E18: ='DenetimDeğişkenleri'!B18 -> 2 | F18: =IF('DenetimDeğişkenleri'!H18=0,'DenetimDeğişkenleri'!B18/('DenetimDeğişkenleri'!B18+'DenetimDeğişkenleri'!C18*Bold+'DenetimDeğişkenleri'!D18+'DenetimDeğişkenleri'!F18+'DenetimDeğişkenleri'!X18),"NR") -> 0.5 | G18: =IF('DenetimDeğişkenleri'!$X$18=0,IF(F18<>"NR",IF(Safety=1,IF(F18<0.9,IF(F18<0.7,"R","Y"),"G"),IF(F18<0.8,IF(F18<0.6,"R","Y"),"G")),"NR"),"R") -> R | H18: ='DenetimDeğişkenleri'!N18-'DenetimDeğişkenleri'!L18 -> 3 | I18: ='DenetimDeğişkenleri'!I18 -> 0 | J18: =IF('DenetimDeğişkenleri'!O18=0,'DenetimDeğişkenleri'!I18/('DenetimDeğişkenleri'!I18+'DenetimDeğişkenleri'!J18*Bold+'DenetimDeğişkenleri'!K18+'DenetimDeğişkenleri'!M18+'DenetimDeğişkenleri'!Y18),"NR") -> NR | K18: =IF('DenetimDeğişkenleri'!$Y$18=0,IF(J18<>"NR",IF(Safety=1,IF(J18<0.9,IF(J18<0.7,"R","Y"),"G"),IF(J18<0.8,IF(J18<0.6,"R","Y"),"G")),"NR"),"R") -> NR | L18: ='DenetimDeğişkenleri'!U18-'DenetimDeğişkenleri'!S18 -> 3 | M18: ='DenetimDeğişkenleri'!P18 -> 0 | N18: =IF('DenetimDeğişkenleri'!V18=0,'DenetimDeğişkenleri'!P18/('DenetimDeğişkenleri'!P18+'DenetimDeğişkenleri'!Q18*Bold+'DenetimDeğişkenleri'!R18+'DenetimDeğişkenleri'!T18+'DenetimDeğişkenleri'!Z18),"NR") -> NR | O18: =IF('DenetimDeğişkenleri'!$Z$18=0,IF(N18<>"NR",IF(Safety=1,IF(N18<0.9,IF(N18<0.7,"R","Y"),"G"),IF(N18<0.8,IF(N18<0.6,"R","Y"),"G")),"NR"),"R") -> NR
A19: 10 | B19: Bakım | C19: MAI | D19: ='DenetimDeğişkenleri'!G19-'DenetimDeğişkenleri'!E19 -> 6 | E19: ='DenetimDeğişkenleri'!B19 -> 4 | F19: =IF('DenetimDeğişkenleri'!H19=0,'DenetimDeğişkenleri'!B19/('DenetimDeğişkenleri'!B19+'DenetimDeğişkenleri'!C19*Bold+'DenetimDeğişkenleri'!D19+'DenetimDeğişkenleri'!F19+'DenetimDeğişkenleri'!X19),"NR") -> 0.5 | G19: =IF('DenetimDeğişkenleri'!$X$19=0,IF(F19<>"NR",IF(Safety=1,IF(F19<0.9,IF(F19<0.7,"R","Y"),"G"),IF(F19<0.8,IF(F19<0.6,"R","Y"),"G")),"NR"),"R") -> R | H19: ='DenetimDeğişkenleri'!N19-'DenetimDeğişkenleri'!L19 -> 6 | I19: ='DenetimDeğişkenleri'!I19 -> 0 | J19: =IF('DenetimDeğişkenleri'!O19=0,'DenetimDeğişkenleri'!I19/('DenetimDeğişkenleri'!I19+'DenetimDeğişkenleri'!J19*Bold+'DenetimDeğişkenleri'!K19+'DenetimDeğişkenleri'!M19+'DenetimDeğişkenleri'!Y19),"NR") -> NR | K19: =IF('DenetimDeğişkenleri'!$Y$19=0,IF(J19<>"NR",IF(Safety=1,IF(J19<0.9,IF(J19<0.7,"R","Y"),"G"),IF(J19<0.8,IF(J19<0.6,"R","Y"),"G")),"NR"),"R") -> NR | L19: ='DenetimDeğişkenleri'!U19-'DenetimDeğişkenleri'!S19 -> 6 | M19: ='DenetimDeğişkenleri'!P19 -> 0 | N19: =IF('DenetimDeğişkenleri'!V19=0,'DenetimDeğişkenleri'!P19/('DenetimDeğişkenleri'!P19+'DenetimDeğişkenleri'!Q19*Bold+'DenetimDeğişkenleri'!R19+'DenetimDeğişkenleri'!T19+'DenetimDeğişkenleri'!Z19),"NR") -> NR | O19: =IF('DenetimDeğişkenleri'!$Z$19=0,IF(N19<>"NR",IF(Safety=1,IF(N19<0.9,IF(N19<0.7,"R","Y"),"G"),IF(N19<0.8,IF(N19<0.6,"R","Y"),"G")),"NR"),"R") -> NR
A20: 11 | B20: Üretim ve Malzeme Akışı Yönetimi | C20: MMFM | D20: ='DenetimDeğişkenleri'!G20-'DenetimDeğişkenleri'!E20 -> 6 | E20: ='DenetimDeğişkenleri'!B20 -> 6 | F20: =IF('DenetimDeğişkenleri'!H20=0,'DenetimDeğişkenleri'!B20/('DenetimDeğişkenleri'!B20+'DenetimDeğişkenleri'!C20*Bold+'DenetimDeğişkenleri'!D20+'DenetimDeğişkenleri'!F20+'DenetimDeğişkenleri'!X20),"NR") -> 1 | G20: =IF('DenetimDeğişkenleri'!$X$20=0,IF(F20<>"NR",IF(Safety=1,IF(F20<0.9,IF(F20<0.7,"R","Y"),"G"),IF(F20<0.8,IF(F20<0.6,"R","Y"),"G")),"NR"),"R") -> G | H20: ='DenetimDeğişkenleri'!N20-'DenetimDeğişkenleri'!L20 -> 6 | I20: ='DenetimDeğişkenleri'!I20 -> 0 | J20: =IF('DenetimDeğişkenleri'!O20=0,'DenetimDeğişkenleri'!I20/('DenetimDeğişkenleri'!I20+'DenetimDeğişkenleri'!J20*Bold+'DenetimDeğişkenleri'!K20+'DenetimDeğişkenleri'!M20+'DenetimDeğişkenleri'!Y20),"NR") -> NR | K20: =IF('DenetimDeğişkenleri'!$Y$20=0,IF(J20<>"NR",IF(Safety=1,IF(J20<0.9,IF(J20<0.7,"R","Y"),"G"),IF(J20<0.8,IF(J20<0.6,"R","Y"),"G")),"NR"),"R") -> NR | L20: ='DenetimDeğişkenleri'!U20-'DenetimDeğişkenleri'!S20 -> 6 | M20: ='DenetimDeğişkenleri'!P20 -> 0 | N20: =IF('DenetimDeğişkenleri'!V20=0,'DenetimDeğişkenleri'!P20/('DenetimDeğişkenleri'!P20+'DenetimDeğişkenleri'!Q20*Bold+'DenetimDeğişkenleri'!R20+'DenetimDeğişkenleri'!T20+'DenetimDeğişkenleri'!Z20),"NR") -> NR | O20: =IF('DenetimDeğişkenleri'!$Z$20=0,IF(N20<>"NR",IF(Safety=1,IF(N20<0.9,IF(N20<0.7,"R","Y"),"G"),IF(N20<0.8,IF(N20<0.6,"R","Y"),"G")),"NR"),"R") -> NR
A21: 12 | B21: Lojistik | C21: LOG | D21: ='DenetimDeğişkenleri'!G21-'DenetimDeğişkenleri'!E21 -> 9 | E21: ='DenetimDeğişkenleri'!B21 -> 8 | F21: =IF('DenetimDeğişkenleri'!H21=0,'DenetimDeğişkenleri'!B21/('DenetimDeğişkenleri'!B21+'DenetimDeğişkenleri'!C21*Bold+'DenetimDeğişkenleri'!D21+'DenetimDeğişkenleri'!F21+'DenetimDeğişkenleri'!X21),"NR") -> 0.8 | G21: =IF('DenetimDeğişkenleri'!$X$21=0,IF(F21<>"NR",IF(Safety=1,IF(F21<0.9,IF(F21<0.7,"R","Y"),"G"),IF(F21<0.8,IF(F21<0.6,"R","Y"),"G")),"NR"),"R") -> Y | H21: ='DenetimDeğişkenleri'!N21-'DenetimDeğişkenleri'!L21 -> 9 | I21: ='DenetimDeğişkenleri'!I21 -> 0 | J21: =IF('DenetimDeğişkenleri'!O21=0,'DenetimDeğişkenleri'!I21/('DenetimDeğişkenleri'!I21+'DenetimDeğişkenleri'!J21*Bold+'DenetimDeğişkenleri'!K21+'DenetimDeğişkenleri'!M21+'DenetimDeğişkenleri'!Y21),"NR") -> NR | K21: =IF('DenetimDeğişkenleri'!$Y$21=0,IF(J21<>"NR",IF(Safety=1,IF(J21<0.9,IF(J21<0.7,"R","Y"),"G"),IF(J21<0.8,IF(J21<0.6,"R","Y"),"G")),"NR"),"R") -> NR | L21: ='DenetimDeğişkenleri'!U21-'DenetimDeğişkenleri'!S21 -> 9 | M21: ='DenetimDeğişkenleri'!P21 -> 0 | N21: =IF('DenetimDeğişkenleri'!V21=0,'DenetimDeğişkenleri'!P21/('DenetimDeğişkenleri'!P21+'DenetimDeğişkenleri'!Q21*Bold+'DenetimDeğişkenleri'!R21+'DenetimDeğişkenleri'!T21+'DenetimDeğişkenleri'!Z21),"NR") -> NR | O21: =IF('DenetimDeğişkenleri'!$Z$21=0,IF(N21<>"NR",IF(Safety=1,IF(N21<0.9,IF(N21<0.7,"R","Y"),"G"),IF(N21<0.8,IF(N21<0.6,"R","Y"),"G")),"NR"),"R") -> NR
A22: 13 | B22: Katmanlı Proses Denetimi ve Yetkinlik Yönetimi | C22: LPASK | D22: ='DenetimDeğişkenleri'!G22-'DenetimDeğişkenleri'!E22 -> 9 | E22: ='DenetimDeğişkenleri'!B22 -> 7 | F22: =IF('DenetimDeğişkenleri'!H22=0,'DenetimDeğişkenleri'!B22/('DenetimDeğişkenleri'!B22+'DenetimDeğişkenleri'!C22*Bold+'DenetimDeğişkenleri'!D22+'DenetimDeğişkenleri'!F22+'DenetimDeğişkenleri'!X22),"NR") -> 0.63636364 | G22: =IF('DenetimDeğişkenleri'!$X$22=0,IF(F22<>"NR",IF(Safety=1,IF(F22<0.9,IF(F22<0.7,"R","Y"),"G"),IF(F22<0.8,IF(F22<0.6,"R","Y"),"G")),"NR"),"R") -> R | H22: ='DenetimDeğişkenleri'!N22-'DenetimDeğişkenleri'!L22 -> 9 | I22: ='DenetimDeğişkenleri'!I22 -> 0 | J22: =IF('DenetimDeğişkenleri'!O22=0,'DenetimDeğişkenleri'!I22/('DenetimDeğişkenleri'!I22+'DenetimDeğişkenleri'!J22*Bold+'DenetimDeğişkenleri'!K22+'DenetimDeğişkenleri'!M22+'DenetimDeğişkenleri'!Y22),"NR") -> NR | K22: =IF('DenetimDeğişkenleri'!$Y$22=0,IF(J22<>"NR",IF(Safety=1,IF(J22<0.9,IF(J22<0.7,"R","Y"),"G"),IF(J22<0.8,IF(J22<0.6,"R","Y"),"G")),"NR"),"R") -> NR | L22: ='DenetimDeğişkenleri'!U22-'DenetimDeğişkenleri'!S22 -> 9 | M22: ='DenetimDeğişkenleri'!P22 -> 0 | N22: =IF('DenetimDeğişkenleri'!V22=0,'DenetimDeğişkenleri'!P22/('DenetimDeğişkenleri'!P22+'DenetimDeğişkenleri'!Q22*Bold+'DenetimDeğişkenleri'!R22+'DenetimDeğişkenleri'!T22+'DenetimDeğişkenleri'!Z22),"NR") -> NR | O22: =IF('DenetimDeğişkenleri'!$Z$22=0,IF(N22<>"NR",IF(Safety=1,IF(N22<0.9,IF(N22<0.7,"R","Y"),"G"),IF(N22<0.8,IF(N22<0.6,"R","Y"),"G")),"NR"),"R") -> NR
A23: 14 | B23: Alt Kademe (Tier N) Tedarikçi Yönetimi | C23: EK | D23: =COUNTIFS('Denetim'!$F:$F,"X") -> 9 | E23: =COUNTIFS('Denetim'!$F:$F,"X",'Denetim'!$O:$O,"OK") -> 5 | F23: =IF(AND('DenetimDeğişkenleri'!$H$6=0,'DenetimDeğişkenleri'!$F$6<('DenetimDeğişkenleri'!$G$6-1-'DenetimDeğişkenleri'!$E$6)/5),'DenetimDeğişkenleri'!$B$6/('DenetimDeğişkenleri'!$B$6+'DenetimDeğişkenleri'!$C$6*Bold+'DenetimDeğişkenleri'!$D$6+'DenetimDeğişkenleri'!$F$6+'DenetimDeğişkenleri'!$X$6),"NR") -> 0.65254237 | G23: =IF(F23<>"NR",IF(F23<0.7,"R",IF(F23<0.9,"Y","G")),"NR") -> R | H23: =COUNTIFS('Denetim'!$F:$F,"X") -> 9 | I23: =COUNTIFS('Denetim'!$F:$F,"X",'Denetim'!$P:$P,"OK") -> 0 | J23: =IF(AND('DenetimDeğişkenleri'!$O$6=0,'DenetimDeğişkenleri'!$M$6<('DenetimDeğişkenleri'!$N$6-1-'DenetimDeğişkenleri'!$L$6)/5),'DenetimDeğişkenleri'!$I$6/('DenetimDeğişkenleri'!$I$6+'DenetimDeğişkenleri'!$J$6*Bold+'DenetimDeğişkenleri'!$K$6+'DenetimDeğişkenleri'!$M$6+'DenetimDeğişkenleri'!$Y$6),"NR") -> NR | K23: =IF(J23<>"NR",IF(J23<0.7,"R",IF(J23<0.9,"Y","G")),"NR") -> NR | L23: =COUNTIFS('Denetim'!$F:$F,"X") -> 9 | M23: =COUNTIFS('Denetim'!$F:$F,"X",'Denetim'!$Q:$Q,"OK") -> 0 | N23: =IF(AND('DenetimDeğişkenleri'!$V$6=0,'DenetimDeğişkenleri'!$T$6<('DenetimDeğişkenleri'!$U$6-1-'DenetimDeğişkenleri'!$S$6)/5),'DenetimDeğişkenleri'!$P$6/('DenetimDeğişkenleri'!$P$6+'DenetimDeğişkenleri'!$Q$6*Bold+'DenetimDeğişkenleri'!$R$6+'DenetimDeğişkenleri'!$T$6+'DenetimDeğişkenleri'!$Z$6),"NR") -> NR | O23: =IF(N23<>"NR",IF(N23<0.7,"R",IF(N23<0.9,"Y","G")),"NR") -> NR
B24: Denetim Özeti Toplam Puan | D24: =SUM(D$10:D22) -> 102 | E24: =SUM(E$10:E22) -> 77 | F24: =IF('DenetimDeğişkenleri'!$H$6=0,'DenetimDeğişkenleri'!$B$6/('DenetimDeğişkenleri'!$B$6+'DenetimDeğişkenleri'!$C$6*Bold+'DenetimDeğişkenleri'!$D$6+'DenetimDeğişkenleri'!$F$6+'DenetimDeğişkenleri'!$X$6),"NR") -> 0.65254237 | G24: =IF(COUNTIF(F$10:F22,"<=0,33")>=2,"R",IF(F24="NR","NR",IF(F24<0.7,"R",IF(F24<0.9,"Y","G")))) -> R | H24: =SUM(H$10:H22) -> 102 | I24: =SUM(I$10:I22) -> 0 | J24: =IF('DenetimDeğişkenleri'!$O$6=0,'DenetimDeğişkenleri'!$I$6/('DenetimDeğişkenleri'!$I$6+'DenetimDeğişkenleri'!$J$6*Bold+'DenetimDeğişkenleri'!$K$6+'DenetimDeğişkenleri'!$M$6+'DenetimDeğişkenleri'!$Y$6),"NR") -> NR | K24: =IF(COUNTIF(J$10:J22,"<=0,33")>=2,"R",IF(J24="NR","NR",IF(J24<0.7,"R",IF(J24<0.9,"Y","G")))) -> NR | L24: =SUM(L$10:L22) -> 102 | M24: =SUM(M$10:M22) -> 0 | N24: =IF('DenetimDeğişkenleri'!$V$6=0,'DenetimDeğişkenleri'!$P$6/('DenetimDeğişkenleri'!$P$6+'DenetimDeğişkenleri'!$Q$6*Bold+'DenetimDeğişkenleri'!$R$6+'DenetimDeğişkenleri'!$T$6+'DenetimDeğişkenleri'!$Z$6),"NR") -> NR | O24: =IF(COUNTIF(N$10:N22,"<=0,33")>=2,"R",IF(N24="NR","NR",IF(N24<0.7,"R",IF(N24<0.9,"Y","G")))) -> NR | P24: İki temel unsur %33 puan alırsa sonuç Kırmızı olur. Puanlama sınırları, güvenlik bileşeninin özelliklerine bağlıdır.
B25: Denetim Sonucu | D25: =IF(G24="G","Önerilir",IF(G24="Y","Aksiyon planıyla önerilir",IF(G24="NR","Değerlendirme Dışı","Önerilmez"))) -> Önerilmez | H25: =IF(K24="G","Önerilir",IF(K24="Y","Aksiyon planıyla önerilir",IF(K24="NR","Değerlendirme Dışı","Önerilmez"))) -> Değerlendirme Dışı | L25: =IF(O24="G","Önerilir",IF(O24="Y","Aksiyon planı tamamlanmadı",IF(O24="NR","Değerlendirme Dışı","Önerilmez"))) -> Değerlendirme Dışı | P25: Yeşil - Önerilir Sarı - Aksiyon planıyla önerilir Kırmızı - Önerilmez Değerlendirme dışı: Gerekliliklerin %90'ından azı puanlanmış; yeniden değerlendirme gerekir.
B26: Genel Yorum

Sheet Özet_Geçici
A2: Tedarikçi Adı | C2: ='Kapak'!B4 -> EKOL GLASS CAM SANAYİ VE TİCARET LİMİTED ŞİRKETİ | H2: Denetimin Kapsamı | P2: ='Kapak'!$B$17 -> 0
A3: Tedarikçi Adresi | C3: ='Kapak'!B5 -> Vakıf Mahallesi, 9. Turan Sokak No: 1/A, Yıldırım/Bursa, Türkiye | H3: Denetim Tarihi | P3: ='Kapak'!A13
A4: Tedarikçi DUNS / COFOR | C4: ='Kapak'!B6 -> COFOR - A02K2H 01 | H4: Denetçi Adı | P4: ='Kapak'!B14 -> 0
A5: Önceki MPA Oranı | H5: Önceki MPA Rengi
D8: Öz Değerlendirme Puanlaması | H8: STELLANTIS Denetim Puanlaması | L8: Aksiyon Planı Puanlaması
A9: Temel Unsurlar | D9: Potansiyel | E9: Toplam | F9: % | G9: Durum | H9: Potansiyel | I9: Toplam | J9: % | K9: Durum | L9: Potansiyel | M9: Toplam | N9: % | O9: Durum | P9: Yorum
A11: 16 | B11: Alt Kademe (Tier N) Tedarikçi Yönetimi | C11: EK
B12: Denetim Özeti Toplam Puan
B13: Denetim Sonucu
B14: Genel Yorum

Sheet Denetim
A1: MRS Sürümü: 8.0 (revizyon tarihi: 16/09/2026) | W1: =IF('TabletParametreleri'!$B$2=W3,"X","") | X1: =IF('TabletParametreleri'!$B$2=X3,"X","") -> X | Y1: =IF('TabletParametreleri'!$B$2=Y3,"X","") | Z1: =IF('TabletParametreleri'!$B$2=Z3,"X","") | AA1: =IF('TabletParametreleri'!$B$2=AA3,"X","") | AB1: =IF('TabletParametreleri'!$B$2=AB3,"X","") | AC1: =IF('TabletParametreleri'!$B$2=AC3,"X","") | AD1: =IF('TabletParametreleri'!$B$2=AD3,"X","") | ... AG1: =IF('TabletParametreleri'!$B$2=AG3,"X","") | AKP1: 3
E2: =COUNTIF($F:$F,"X") -> 9 | O2: Tedarikçi | P2: STELLANTIS GÜNCEL DENETİMİ | W2: Olası denetimler
A3: Madde | B3: Gereklilik | F3: EK PUANLAMA | G3: TEMEL | H3: İLAVE | I3: MADDE | K3: ÜRETİM SAHASI | L3: Kriter No | M3: Kriter gerekliliği | N3: İncelenecek Hususlar | O3: Kriter Puanlaması (OK / NOK) | P3: Kriter Puanlaması (OK / NOK) | Q3: Kriter Aksiyon Planı [GİZLİ] | R3: Tedarikçi Yorumu | S3: Stellantis Yorumu | W3: =Tableau1[[#Headers],[MPA1]] -> MPA1 | X3: =Tableau1[[#Headers],[NSA]] -> NSA | Y3: =Tableau1[[#Headers],[MPA2]] -> MPA2 | Z3: =Tableau1[[#Headers],[PPQ_KOM]] -> PPQ_KOM | AA3: =Tableau1[[#Headers],[PPQ_TKO]] -> PPQ_TKO | AB3: =Tableau1[[#Headers],[PPQ_OT]] -> PPQ_OT | AC3: =Tableau1[[#Headers],[PPQ_PPAP]] -> PPQ_PPAP | AD3: =Tableau1[[#Headers],[PPQ_End_Dev]] -> PPQ_End_Dev | AE3: =Tableau1[[#Headers],[PPQ_Mass_prod]] -> PPQ_Mass_prod | AF3: =Tableau1[[#Headers],[PPQ_Safe_Launch]] -> PPQ_Safe_Launch | AG3: =Tableau1[[#Headers],[PPQ_PFMEA]] -> PPQ_PFMEA
A4: Tesis Kurumsal Yönetimi | Y4: 2 | AI4: X
A5: CMP1 | B5: IATF 16949 ve Müşteri Dokümantasyonu | F5: X | G5: X | L5: CMP11 | M5: Tesis, IATF 16949 sertifikasına sahiptir. | N5: Kontrol edin: Denetim öncesinde sertifikanın geçerli olduğunu doğrulayın: - Teklif listesinde bulunmuyorsa tedarikçiden sertifika numarasını isteyin. - Sertifika yoksa (geri çekilmiş, iptal edilmiş veya süresi dolmuşsa) ya da askıya alınmışsa bir aksiyon planının uygulandığını doğrulayın. Denetim sırasında son denetimi (uygunsuzluklar ve aksiyon planı) inceleyin. Yeni veya sıfırdan kurulan bir tedarikçi için: - Sertifikasyon denetimi en geç SOP öncesine planlanmalıdır. - Bu mümkün değilse SOP öncesinde uygunluk mektubu alınması planlanmalıdır. - 01598_15_06479 referanslı sıfırdan kurulan tesis kontrol listesinin 3.5 'tesis sertifikasyonu' maddesine uygun aksiyon planı bulunmalıdır. | O5: NOK | Q5: =IF(P5="","",IF('Aksiyon Planı'!$N5="",P5,'Aksiyon Planı'!$N5)) | R5: Tesisin aktif bir IATF 16949 sertifikası bulunmamaktadır. Şu anda belgelendirme kuruluşlarıyla görüşüyoruz. Henüz kesin bir belgelendirme denetimi tarihi planlanmamıştır. Yaklaşan müşteri denetiminden önce bu tarihi kesinleştirmeyi ve resmî olarak belirlemeyi hedefliyoruz. | X5: X | Y5: X | Z5: X | AA5: Y | AB5: Y | AC5: Y | AI5: X
F6: X | G6: X | L6: CMP12 | M6: STLA gereklilikleri dikkate alınmaktadır. | N6: Kontrol edin: Tedarikçiden B2B portalına nasıl eriştiğini göstermesini isteyin. Temel dokümanların bilindiğini doğrulayın (ör. QRS, MRS ve eğitimi, GSQN-001 vb.). | O6: NR | Q6: =IF(P6="","",IF('Aksiyon Planı'!$N6="",P6,'Aksiyon Planı'!$N6)) | R6: STLA B2B portalına erişimimiz bulunmamaktadır. Portal kullanımını gösteremiyor veya QRS ve MRS gibi STLA'ya özel dokümanları indiremiyoruz. Genel otomotiv kalite gereklilikleri sistemimizde uygulanmaktadır. Portal erişimi sağlandıktan sonra STLA'ya özel gereklilikleri sistemimize dahil edeceğiz. | X6: X | Y6: X | AI6: X
F7: X | G7: X | L7: CMP13 | M7: MPA öz değerlendirmeleri izlenmekte ve STLA ile paylaşılmaktadır. | N7: Kontrol edin: - Tedarikçinin MPA gerekliliklerine yönelik eksikleri belirlediğini ve düzeltici aksiyon planı uyguladığını doğrulayın. - İstenen seviyeye ulaşmak veya bu seviyeyi korumak için yıllık öz değerlendirmenin yönetildiğini doğrulayın (MPA sonucu ≥ %85). | O7: NR | Q7: =IF(P7="","",IF('Aksiyon Planı'!$N7="",P7,'Aksiyon Planı'!$N7)) | R7: Aktif bir MPA öz değerlendirmemiz bulunmamaktadır. Bu aşamada yıllık değerlendirme sonuçlarını STLA ile paylaşamıyoruz. Resmî proje başlangıcından sonra eksikleri belirleyip düzeltici aksiyon planı uygulayacağız. | X7: X | Y7: X | Z7: X | AA7: Y | AB7: Y | AC7: Y | AI7: X
A8: CMP2 | B8: Acil Durum Planları (İş Sürekliliği Planı) | G8: X | L8: CMP21 | M8: Kapsam dahilindeki temel BT, üretim, tedarik zinciri, insan kaynakları ve doğal afet riskleri belirlenmiştir. | N8: Risk belirlemenin (ör. 5M) ve risk azaltma düzeylerinin yeterliliğini kontrol edin: - Yangın: sprinkler kapsamı vb. - Sel: koruyucu setler vb. - Deprem: depreme karşı koruma vb. - Elektrik kesintisi: alternatif enerji kaynağının bulunması vb. - Su yetersizliği: stok vb. - İş gücü: işe alım vb. - Bakım: yedek parça bulunabilirliği vb. - Tedarikçiler: Tier 2 risk haritası vb. - Diğer: bitmiş ürün stoku vb. | O8: NOK | Q8: =IF(P8="","",IF('Aksiyon Planı'!$N8="",P8,'Aksiyon Planı'!$N8)) | R8: Tesiste doğal afetlere yönelik yazılı bir acil durum planı bulunmakta ve BT yedeklemeleri çalışmaktadır. Ancak elektrik kesintileri için tesiste yedek jeneratör bulunmaması önemli bir altyapı eksikliğidir. Genel elektrik kesintisi riski, devrede olan yedek ekipmanla tam olarak azaltılmamıştır ve bu durum kesintisiz üretim faaliyetlerini doğrudan tehdit etmektedir. | X8: X | Y8: X | AI8: X
G9: X | L9: CMP22 | M9: Riskler, kapsamlı bir risk azaltma planıyla birlikte düzenli olarak gözden geçirilmektedir. | N9: Tedarikçinin aşağıdaki uygulamalarını örnekler üzerinden kontrol edin: - Riskleri değerlendirme ve azaltma - Yeni veya ortaya çıkan riskleri ele alma - Kritik durumları yönetime bildirme - Olası kesintileri öngörmek için erken ve zayıf sinyalleri kullanma - Tekrarı önlemek için öğrenilen dersleri uygulama | O9: OK | Q9: =IF(P9="","",IF('Aksiyon Planı'!$N9="",P9,'Aksiyon Planı'!$N9)) | R9: Risk azaltma planları düzenli olarak gözden geçirilip güncellenmektedir. Geçmiş olaylardan öğrenilen dersler mevcut risk değerlendirmelerine başarıyla dahil edilmektedir. Kritik durumlar doğrudan tesis yönetim ekibine iletilmektedir. Ancak erken ve zayıf sinyallerin toplanması ve analizine yönelik iç süreç henüz gayriresmîdir ve daha sistematik, veriye dayalı bir yaklaşım gerektirmektedir. Durum OK olarak değerlendirilmiştir. | X9: X | Y9: X | AI9: X
G10: X | L10: CMP23 | M10: Bilgi sistemine izinsiz girişin önlenmesi ile veri yedekleme ve kurtarma için prosedürler bulunmaktadır (ör. EDI, SAP). Bunlar uygun durumlarda düzenli olarak test edilmekte; planlar denetlenmekte ve tatbikatlar yapılmaktadır. | N10: - Prosedürü isteyin ve bir örneği kontrol edin. - Siber saldırılara karşı risk azaltma planının yeterliliğini değerlendirin: ağ erişim kısıtlamaları, USB yasağı, BT ekibinin sahte mesajlarla yaptığı testler. | O10: OK | Q10: =IF(P10="","",IF('Aksiyon Planı'!$N10="",P10,'Aksiyon Planı'!$N10)) | R10: Bilgi sistemlerine izinsiz girişin önlenmesi, düzenli veri yedekleme ve felaket kurtarma için resmî prosedürler oluşturulmuş ve uygulanmaktadır (kritik ERP, SAP ve EDI sistemleri dahil). Yedeklerin bütünlüğü ve sunucu geri yükleme protokolleri rutin olarak test edilmektedir. Sıkı ağ erişim kısıtlamaları, iş istasyonlarında fiziksel USB bağlantı noktalarının kilitlenmesi ve çalışanların dış saldırılara karşı dikkatini doğrulamak üzere BT güvenlik ekibinin düzenli olarak yürüttüğü kimlik avı farkındalık simülasyonları dahil siber güvenlik önlemleri aktif olarak uygulanmaktadır. | X10: X | Y10: X | AI10: X
A11: CMP3 | B11: Dış Kaynak ve Alt Kademe (Tier N) Tedarikçi Yönetimi | F11: X | G11: X | L11: CMP31 | M11: Tedarik kaynağı olarak seçilebilir tedarikçi olma kriterleri tanımlanmıştır. | N11: Tedarikçi seçimine ait dokümantasyonu kontrol edin. Seçim grup düzeyinde yapılıyorsa Tier 2 durumunun üretim tesisi tarafından bilindiğini ve performans değerlendirmesinde dikkate alındığını doğrulayın. | O11: OK | Q11: =IF(P11="","",IF('Aksiyon Planı'!$N11="",P11,'Aksiyon Planı'!$N11)) | R11: Yeni tedarikçilerin değerlendirilmesi, yeterliliklerinin doğrulanması ve onaylanması (tedarik kaynağı olarak seçilebilirlik) için resmî kriterler ve standart prosedürler oluşturulmuştur. Tedarikçi seçim sözleşmeleri kurumsal satın alma kurallarıyla yönetilirken üretim tesisimiz, onaylı tüm alt kademe (Tier N) tedarikçileri doğrudan izleyebilmektedir. Alt tedarikçilerin kalite göstergeleri, teslimat güvenilirliği ve lojistik uygunluğunu kapsayan performansı sistematik olarak takip edilmekte ve iç tedarikçi değerlendirme ve performans izleme süreçlerine dahil edilmektedir. | X11: X | Y11: X | AI11: X
F12: X | G12: X | L12: CMP32 | M12: Tier 2 performansı izlenmektedir. Sapma durumunda eskalasyon Tier 1 tarafından yönetilmektedir. | N12: - Denetim öncesinde Tier 2 kaynaklı müşteri şikâyeti olup olmadığını kontrol edin. Kontrol edin: - Performans göstergeleri için eşiklerin tanımlanıp tanımlanmadığı (ör. teklif listesi puanlaması) - Hedef karşılanmadığında sınırlama önlemleri, aksiyon planları (ör. kontrollü sevkiyat, yeni iş verilmesinin durdurulması vb.) ve çıkış kriterleriyle eskalasyon uygulanıp uygulanmadığı | O12: OK | Q12: =IF(P12="","",IF('Aksiyon Planı'!$N12="",P12,'Aksiyon Planı'!$N12)) | R12: Tier 2 tedarikçi performansı, tanımlı göstergeler ve eşiklerle izlenmektedir. Sınırlama önlemleri ve çıkış kriterleri dahil eskalasyon süreçleri standart Tedarikçi Eskalasyon Bildirim formumuzla yürütülmektedir. Ancak Tier 2 performans eğilimlerine ait uzun dönem geçmiş veriler hâlen elle takip edilmekte ve otomatik yazılım entegrasyonu bulunmamaktadır. | X12: X | Y12: X | AI12: X
F13: X | G13: X | L13: CMP33 | M13: Montajlı parçalarda yalnızca onaylı (ör. PPAP A) bileşenler/malzemeler kullanılmaktadır. Giriş kontrolü yapılmakta ve yönetilmektedir. Kontrol sıklığı, tedarikçi KPI'larıyla uyumludur. | N13: - Giriş kontrolünün kritik özellikleri ve sonraki proseslerde kontrol edilmeyen özellikleri kapsadığını, sıklıkların kontrol planıyla uyumlu olduğunu doğrulayın. - Teslim alındıktan sonra üretime serbest bırakılan malzemelerin tanımlanmasını kontrol edin. - Aşağıdaki durumlarda sıklık güncelleme kuralları bulunduğunu doğrulayın: Giriş kontrolünde uygunsuzluk bulunması Tier 2 kaynaklı müşteri şikâyeti Performansın kötüleşmesi Yeni/değiştirilmiş parça için önleyici sınırlama önlemlerinin uygulanması | O13: OK | Q13: =IF(P13="","",IF('Aksiyon Planı'!$N13="",P13,'Aksiyon Planı'!$N13)) | R13: Tüm ham maddeler ve bileşenler için kontrol planına göre sistematik giriş kontrolü yapılmaktadır. Montajlı parçalarda kullanım için yalnızca onaylı malzemeler serbest bırakılmaktadır. Ancak Tier 2 performansındaki belirli kötüleşmelere göre kontrol sıklıklarının dinamik olarak güncellenmesi, otomatik sistem uyarısı yerine hâlen elle yürütülmektedir. | X13: X | Y13: X | AB13: X | AC13: X | AI13: X
A14: Grup Kurumsal Yönetimi | Y14: 2 | AI14: X
A15: CMG1 | B15: Proje Yönetimi | G15: X | L15: CMG11 | M15: Üretim tesisi, fizibiliteyi değerlendirmek amacıyla yeni projelere dahil edilmektedir. | N15: Proje sorumluluğunun aşağıdaki işler için atanıp atanmadığını kontrol edin: - Ürünün üretim prosesindeki yapılabilirliğinin analizi - Sanayileşme sürecinin takibi (ör. üretim proses mühendisi; üretim ve kontrol takımlarının doğrulanması için laboratuvar) PPQ için: Tedarikçinin Kalite ve/veya Proje Yöneticisinin STLA APQP gereklilikleri konusunda eğitimli olduğunu doğrulayın. Tedarikçinin proje takibi için üretim tesisinden bir sorumlu atadığını kontrol edin. | O15: OK | Q15: =IF(P15="","",IF('Aksiyon Planı'!$N15="",P15,'Aksiyon Planı'!$N15)) | R15: Üretim tesisi, ilk RFQ ve APQP başlangıç aşamalarından itibaren yeni ürün geliştirme ve mühendislik fizibilite incelemelerine tam olarak dahil edilmektedir. Tüm üretim hücrelerinde teknik fizibilite değerlendirmeleri yapmak, deneme üretimlerini koordine etmek ve test laboratuvarımızla birlikte üretim ve kontrol takımlarını doğrulamak için tesiste özel bir Proje Yöneticisi ve Üretim Proses Mühendisi resmî olarak atanmıştır. Atanan proje liderleri ve kalite mühendisleri, otomotiv APQP kilometre taşları ve müşteriye özel devreye alma gerekliliklerine hâkimdir. Tesis temsilcileri, disiplinler arası proje değerlendirmelerine aktif olarak katılarak sorunsuz sanayileşmeyi ve kilometre taşlarının üretim tesisinden titizlikle takibini sağlamaktadır. | X15: X | Y15: X | Z15: X | AA15: X | AB15: Y | AC15: Y | AI15: X
G16: X | L16: CMG12 | M16: Tedarikçinin proje yönetimi tüm görevleri dikkate almakta ve müşterinin proje takvimi/gereklilikleriyle uyumlu yürütülmektedir. Gecikme/sapma durumunda aksiyon planları uygulanmakta ve müşteri bilgilendirilmektedir. | N16: PPQ için: Tedarikçinin kendi parçaları ve orta/yüksek riskli alt bileşenleri için aşağıdaki unsurları içeren bir zaman planı var mı? 1. Proje ile üretim tesisi arasındaki sorumluluk devrini kontrol edin. 2. Kritik alt kademe bileşenlerin takvimi 3. PPQ, CAT, DV/PV testleri ve PPAP dahil APQP aşama kapıları/teslimatları NSA veya MPA'da bir örnek üzerinden tedarikçinin proje yönetim sürecini inceleyin: 1. Ürün ve proses tasarım doğrulaması (DV/PV testleri, PPQ), kapasite değerlendirmesi (CAT) ve parça onayı (PPAP) dahil APQP aşama kapıları/teslimatları 2. Takım devreye alma başlangıcı (TKO), seri takımdan parça (OT), seri takım ve prosesten parça (OTOP) gibi temel adımlarla kritik takım/ekipman ve ölçüm cihazı teslimatları 3. Kritik özelliklerin yeterlilik ilerlemesi dahil her üretim aşamasında beklenen parça olgunluğu (ör. parçaların prototip veya geçici takımlardan üretilmesi, görünüm parçalarının istenen seviyede olması) | O16: NR | Q16: =IF(P16="","",IF('Aksiyon Planı'!$N16="",P16,'Aksiyon Planı'!$N16)) | R16: Puanlanmadı (NR). STLA'ya özel APQP takvim gereklilikleriyle uyumu değerlendirebileceğimiz aktif bir Stellantis projemiz bulunmamaktadır. Mevcut müşterilerimiz için standart proje yönetimi takvimlerini kullanıyoruz. Ancak mevcut ana planlama aracımız PPQ, CAT ve OTOP gibi STLA'ya özel kilometre taşlarıyla entegre değildir. Resmî proje başlangıcında bu teslimatları izlemek için proje yönetimi yazılımımızı güncelleyeceğiz. | X16: X | Y16: X | Z16: X | AA16: X | AB16: X | AC16: X | AI16: X
G17: X | L17: CMG13 | M17: Programın başlangıcından itibaren ihtiyaç duyulacak yeni yetkinlikleri/personeli erken belirlemek için resmî bir süreç bulunmaktadır. | N17: Kontrol edin: - Projeleri takip etmek ve SOP için iş istasyonunda parça üretmek üzere gerekli kaynaklar belirlenmiş ve hazır mı? - Tesisin genel eğitim planı, yeni prosesler için gerekli yetkinliklerin (ör. yeni model lehimleme prosesi) kazandırılmasını ve projenin SOP aşamasında ihtiyaç duyulan yetkin personel hedefine (yetkinlik matrisi) ulaşılmasını sağlayacak şekilde güncellenip takip ediliyor mu? | O17: OK | Q17: =IF(P17="","",IF('Aksiyon Planı'!$N17="",P17,'Aksiyon Planı'!$N17)) | R17: Program başlangıcından itibaren gerekli personeli ve yeni yetkinlikleri belirleyen resmî bir süreç uygulanmaktadır. Genel tesis eğitim planı ve yetkinlik matrisleri mevcut operasyonlar için düzenli olarak güncellenmektedir. Ancak şu anda üretim başlangıcına (SOP) yaklaşan aktif bir STLA projemiz bulunmadığından STLA üretim istasyonlarına özel eğitim planı ve hedef yetkinlik matrisi henüz doldurulmamış veya doğrulanmamıştır. | X17: X | Y17: X | Z17: X | AA17: X | AB17: Y | AC17: Y | AI17: X
A18: CMG2 | B18: Ürün/Proses Yeterlilik Onayı | G18: X | L18: CMG21 | M18: Üretim prosesinin geliştirilmesi ve yeterlilik onayı, PPQ öz değerlendirmesini ve prosese özel denetimleri (ör. STLA proses kontrol listeleri) kapsamaktadır. | N18: Yeterlilik onayı sürecinin, onay öncesinde aşağıdakileri içeren bir iç denetimi kapsadığını doğrulayın: - Tedarikçinin her aşama kapısında yaptığı PPQ öz değerlendirmesi - STLA tarafından istenmişse AQR uygulaması - Alternatif prosesler, izin verilen yeniden işleme operasyonları vb. Yeni proje, başka tesisten transfer veya yeni üretim hattı için yeni bina/ekipman/takım vb. gerekip gerekmediğini ve yeterlilik onayı sürecinin ürün/proses değişiklikleriyle uyumunu kontrol edin. | O18: NR | Q18: =IF(P18="","",IF('Aksiyon Planı'!$N18="",P18,'Aksiyon Planı'!$N18)) | R18: Puanlanmadı (NR). Şu anda üretim prosesi yeterlilik onayı aşamasında aktif bir STLA projemiz bulunmamaktadır. Bu nedenle STLA'ya özel PPQ öz değerlendirmeleri ve AQR uygulamaları değerlendirme için gösterilememektedir. Standart iç denetimlerimiz genel yeni proses doğrulamalarını kapsamaktadır. Ancak STLA'ya özel aşama kapısı gerekliliklerinin iç denetim prosedürlerimize sistematik olarak dahil edilmesi henüz tamamlanmamıştır. | X18: X | Y18: X | AB18: X | AC18: X | AI18: X
F19: X | G19: X | L19: CMG22 | M19: Yeterlilik onayı süreci, dış kaynaklı tüm üretim proseslerini veya Tier 2 bileşenleri kapsamaktadır. | N19: Kontrol edin: - Tedarikçi, özellikle kritik bileşenler veya proseslerde Tier 2 ürün ve proses yeterlilik onayını sürekli takip ediyor mu? - Tier 1, kendi ürün/proses onayından önce Tier 2 ürün/proses onayını (tüm alt bileşenler için PPAP veya eşdeğeri) tamamlıyor mu? Aksi durumda aksiyon planları ve karşı önlemlerle bir sapma izni alınmış mı (ör. onay kabul edilene kadar ilave kontroller)? - Tier 2 onay sürecinde denetim veya öz denetim gerekiyor mu ve hangi kanıtlar isteniyor? | O19: OK | Q19: =IF(P19="","",IF('Aksiyon Planı'!$N19="",P19,'Aksiyon Planı'!$N19)) | R19: Tedarikçi yeterlilik onayı süreci, Tier 2 bileşenlerin ve dış kaynaklı üretim proseslerinin üretimde kullanılmadan önce onaylanmasını gerektirir. İlgili onay ve yeterlilik kayıtları, onaylı tedarikçi listesiyle birlikte incelenmektedir. Giriş kontrolü sürekli uygunluk doğrulamasını destekler ancak proses veya bileşen yeterlilik onayının yerine geçmez. Tamamlanmamış STLA'ya özel gerekliliklerin alt tedarikçilere aktarılması CMG33 kapsamında ayrıca takip edilmektedir. | X19: X | Y19: X | AB19: X | AC19: X | AI19: X
G20: X | L20: CMG23 | M20: Kontrol planında listelenen seri üretim takımları, makineler ve yerleşim, şartnamelere uygun olarak doğrulanmış ve nihai konumlarına yerleştirilmiştir. | N20: - İş istasyonu/üretim alanı yerleşim planı, proseste kullanılan tüm üretim/kontrol ekipmanı ve takımları ile malzeme depolama alanlarını (WIP/tampon stoklar/uygunsuz malzeme/hurda-yeniden işleme/onarım ve ham madde/alt bileşen depoları) gösteriyor mu? - Takım ve makineler nihai/seri üretim tipinde mi ve kontrol planındaki nihai konumlarına yerleştirilmiş mi? - Yeni veya yenilenmiş tüm tesis/ekipman/takım/kontrol cihazları için şartnamelere uygunluk (yeterlilik ve kapasite) yapısal bir yaklaşımla doğrulanıyor mu? Ölçüm cihazlarında kalibrasyon da kapsanıyor mu? Proses ve iş istasyonu yerleşimi, operasyon atlanmasını ve benzer parçaların karışmasını önleyecek şekilde tasarlanmış mı? | O20: OK | Q20: =IF(P20="","",IF('Aksiyon Planı'!$N20="",P20,'Aksiyon Planı'!$N20)) | R20: Kontrol Planında listelenen tüm seri üretim makineleri, özel cam işleme takımları ve kontrol fikstürleri tamamen doğrulanmış, yeterlilik testleri yapılmış ve nihai üretim yerlerinde devreye alınmıştır. Tesis ve iş istasyonu yerleşimleri tüm üretim hücrelerini, hat içi WIP tamponlarını, uygunsuz ürün karantina bölgelerini ve ham madde depolarını açıkça belirtmektedir. Ekipman yeterlilik (Cmk/Ppk) ve kapasite çalışmaları mühendislik şartnamelerine uyumu doğrulamakta, tüm kontrol mastarları resmî olarak kalibre edilmektedir. İş istasyonları, operasyon atlanmasını ve parça karışmasını önleyen fiziksel poka-yoke durdurucularla ergonomik ve sıralı şekilde düzenlenmiştir. | X20: X | Y20: X | AB20: X | AC20: X | AI20: X
A21: CMG3 | B21: Kritik Özelliklerin Tanımlanması ve Kontrolü | G21: X | L21: CMG31 | M21: Müşteri onaylı teknik resimler ve STLA Parça Kontrol Standardı (PIS - kritik özellikler), en güncel değişiklik seviyesinde üretim tesisinde bulunmaktadır. | N21: Kontrol edin: - Fonksiyonel ve teknik özelliklerin listesi (GD&T veya CTF) - PIS'in teknik resmin en son sürümüne göre tamamlanmış olması | O21: NR | Q21: =IF(P21="","",IF('Aksiyon Planı'!$N21="",P21,'Aksiyon Planı'!$N21)) | R21: Şu anda aktif bir Stellantis projemiz bulunmamaktadır ve tesisimiz için STLA'ya özel PIS alınmamış veya yayımlanmamıştır. Mevcut müşteri operasyonlarında kullanılan dokümantasyon, iç doküman kontrol sürecimizle yönetilmektedir. İlerideki STLA'ya özel teknik resimler ve kontrol gereklilikleri, sözleşmeli Tier 1 müşterimiz aracılığıyla resmî olarak iletildiğinde incelenip uygulanacaktır. Bu kriter mevcut aşamada NR olarak kalmaktadır. | X21: X | Y21: X | AB21: X | AC21: X | AD21: X | AE21: X | AI21: X
G22: X | L22: CMG32 | M22: Tüm kritik özellikler dokümantasyona aktarılmıştır (Akış şeması ==> PCP veya PIS ==> PFMEA ==> Kontrol Planı arasında bağlantı ve uyum sağlanmıştır). | N22: Kontrol edin: - Dokümanlar arası bağlantılar uygun sembollerle açıkça belirtilmiş ve birebir eşleşiyor mu? - Tüm kritik özellikler dokümantasyonda (PFMEA, Kontrol Planı, iş talimatları, ambalajlama ve etiketleme) yer alıyor mu? - Türetilmiş akışlar (ör. yeniden işleme) dahil operasyonlar tüm dokümanlarda bulunuyor mu? - Özel özellikleri etkileyen proses parametreleri analiz edilmiş mi (ör. toleranslar, geçme, yüzey kalitesi, güvenilirlik, dayanıklılık)? - Operatörler kritik özellikleri biliyor mu? | O22: NOK | Q22: =IF(P22="","",IF('Aksiyon Planı'!$N22="",P22,'Aksiyon Planı'!$N22)) | R22: Mevcut müşteri ürünlerinde belirlenen kritik özellikler; Proses Akışı, iç kontrol dokümanları, PFMEA ve Kontrol Planında çapraz referanslarla ilişkilendirilmiştir. Bu referansların tutarlılığını korumak için doküman revizyonları incelenmektedir. Bu değerlendirme mevcut müşteri operasyonlarına ilişkindir ve STLA'ya özel bir dokümantasyon paketinin onayı anlamına gelmez. İlerideki STLA'ya özel özellikler, sözleşmeli Tier 1 müşterimiz aracılığıyla resmî olarak iletildikten sonra dahil edilecektir. | X22: X | Y22: X | AI22: X
F23: X | G23: X | L23: CMG33 | M23: Müşteriye özel gereklilikler Tier N tedarikçilerde uygulanmaktadır: - Ürün ve proses kritik özelliklerinin teknik şartnameleri - Ürün ve prosese özel standartlar - Uygulanması gereken prosedürler (ör. PPAP, PFMEA vb.) - İzlenebilirlik, FIFO ve etiketleme gereklilikleri | N23: Kontrol edin: - Tier 1, kritik özellikler listesi (PIS) dahil teknik şartnameyi Tier 2'ye iletmiş ve kalite gerekliliklerini (ör. AQR, PFMEA, Kalite Planlaması, Kontrol Planı, Sürekli Geçerli Gereklilikler/Proses Değişikliği kuralları vb.) bildirmiş mi? - Tier 2 teklif dosyası teknik/proses fizibilitesini içeriyor mu? Kontrollerin etkinliğini doğrulayın. | O23: NOK | Q23: =IF(P23="","",IF('Aksiyon Planı'!$N23="",P23,'Aksiyon Planı'!$N23)) | R23: STLA'ya özel fonksiyonel ve teknik özellikler (GD&T ve CTF) hâlen iç mühendislik incelemesinde olduğundan alt tedarikçilerimize henüz aktarılmamıştır. Bu nedenle Tier N tedarikçilerin Parça Kontrol Standardını (PIS), güncellenmiş PFMEA beklentilerini veya STLA'ya özel izlenebilirlik ve etiketleme gerekliliklerini aldığını gösteremiyoruz. Ayrıca mevcut alt tedarikçi teklif dosyalarında, STLA'ya özel bu kriterlere karşı zorunlu teknik ve proses fizibilitesi doğrulamaları eksiktir. | X23: X | Y23: X | Z23: X | AA23: X | AB23: X | AC23: X | AD23: X | AE23: X | AI23: X
A24: Hızlı Müdahale | W24: 1 | Y24: 1 | AI24: X
A25: FR1 | B25: Günlük yönetim toplantısı | G25: X | K25: X | L25: FR11 | M25: Üretim üst yönetiminin yönettiği, farklı fonksiyonların katıldığı (en az Üretim, Kalite, Lojistik, Bakım), günlük ve kısa bir hızlı müdahale yönetim toplantısı yapılmaktadır. | N25: Kontrol edin: - Toplantı için ayrılmış alan bulunması (tercihen üretim sahasında) - Toplantıyı destekleyen bilgilerin sergilenmesi - Her gün düzenli olarak planlanmış toplantı yapılması - Toplantının RTR (üretim için gerekli koşullar), iş sağlığı/güvenliği, iç/dış sorunlar ve büyük arızaları kapsaması | O25: OK | Q25: =IF(P25="","",IF('Aksiyon Planı'!$N25="",P25,'Aksiyon Planı'!$N25)) | R25: Tesise bugüne kadar dış müşteri şikâyeti ulaşmamıştır. Operasyonel Hızlı Müdahale toplantıları yapılandırılmıştır ve üretim yönetimi ile farklı fonksiyonların (Üretim, Kalite, Bakım, Lojistik) katılımıyla her gün üretim sahasında yapılmaktadır. Toplantılarda RTR gereklilikleri, güvenlik durumu, iç kalite/hurda eğilimleri ve büyük arızalar sistematik olarak incelenmektedir. Gerçek zamanlı görüşmeleri destekleyen görsel panoların geliştirilmesine yönelik çalışmalar sürmektedir. | W25: X | X25: X | Y25: X | AD25: X | AE25: X | AI25: X
G26: X | K26: X | L26: FR12 | M26: FR sürecinin görsel gösterimi (pano/alan) önemli sorunların ve değişiklik noktalarının takibini sağlamaktadır. Pano, her aksiyon için uygun çıkış kriterleri, zaman planı ve sorumlu bilgilerini içermektedir. | N26: Kontrol edin: - Çıkış kriterlerini içeren ve düzenli güncellenen Görsel Yönetim panosu bulunması - Her madde için hedef tarih belirlenmesi ve sürelere uyulması | O26: OK | Q26: =IF(P26="","",IF('Aksiyon Planı'!$N26="",P26,'Aksiyon Planı'!$N26)) | R26: Dış müşteri kalite sorunu bulunmadığından, Hızlı Müdahale görsel pano yapısı iç üretim sorunlarını ve 4M değişiklik noktalarını izlemek amacıyla üretim sahasında oluşturulmuştur. Pano yapısı, terminlere uyumu sağlamak için açık çıkış kriterleri, belirlenmiş aksiyon sorumluları ve hedef tarihler içermektedir. Tamamlanan aksiyonların sistematik arşivlenmesi sürekli takip edilmektedir. | W26: X | X26: X | Y26: X | AB26: X | AC26: X | AD26: X | AE26: X | AI26: X
G27: X | K27: X | L27: FR13 | M27: Her temel alan için tanımlı hedefleri içeren bir KPI panosu bulunmakta ve ekip performans ile ilerlemeyi izlemek üzere ana KPI'ları düzenli olarak incelemektedir. | N27: Kontrol edin: - KPI'ların (en az Güvenlik, Üretim, Kalite, Lojistik, Bakım) FR alanında görsel olarak sunulması - KPI'ların FR toplantısı için güncellenmesi (ör. üretim sonuçları, kalite sorunları, hurda vb.) | O27: OK | Q27: =IF(P27="","",IF('Aksiyon Planı'!$N27="",P27,'Aksiyon Planı'!$N27)) | R27: Dış müşteri kalite göstergelerinde bildirilen sorun sayısı sıfırdır. KPI takip yapısı üretim sahasındaki Hızlı Müdahale alanında görsel olarak sürdürülmekte; Güvenlik, Üretim, Kalite, Lojistik ve Bakım başlıklarında açık hedefler tanımlanmaktadır. KPI eğilimleri, vardiya çıktıları ve iç hurda verileri günlük operasyon toplantılarında düzenli olarak güncellenip incelenmektedir. Üretim kayıtlarından görsel panoya veri aktarımını otomatikleştirme çalışmaları sürmektedir. | W27: X | X27: X | Y27: X | AB27: X | AC27: X | AI27: X
A28: FR2 | B28: Eskalasyon Süreci | G28: X | K28: X | L28: FR21 | M28: Operatörden tesis kalite yöneticisine kadar sorumlulukları açıkça tanımlanmış, tüm iç ve dış sorunları kapsayan standart bir eskalasyon süreci bulunmaktadır. | N28: Standart eskalasyon sürecinde aşağıdakilerin tanımlandığını kontrol edin: - Eskalasyon seviyeleri - Her yönetim düzeyinin sorumluluğu (operatörler, ekip liderleri, üst yönetim) - Tetikleyiciler ve zamanlama - Zorunlu aksiyonlar - Çıkış kriterleri | O28: OK | Q28: =IF(P28="","",IF('Aksiyon Planı'!$N28="",P28,'Aksiyon Planı'!$N28)) | R28: Müşteri şikâyeti sayısı sıfır olduğundan dış müşteri eskalasyon protokolleri tetiklenmemiştir. Operatörlerden tesis kalite yöneticisine uzanan standart iç eskalasyon yapısı oluşturulmuş; operasyon seviyeleri, sayısal hata tetikleyicileri, zorunlu sınırlama önlemleri ve eskalasyondan çıkış kriterleri tanımlanmıştır. Simüle edilmiş eskalasyon koşullarında operatörlerin tepki verebilirliğini doğrulamak üzere düzenli vardiya tatbikatları yapılmasına odaklanılmaktadır. | W28: X | X28: X | Y28: X | AB28: X | AC28: X | AD28: X | AE28: X | AI28: X
G29: X | K29: X | L29: FR22 | M29: Standart, üretim sahasında erişilebilirdir. Tüm yönetim seviyeleri tarafından bilinmekte ve uygulanmaktadır. | N29: Kontrol edin: - Eskalasyon standardının tesiste herkesçe görülebilecek şekilde asılmış olması - Müdahale standardının operasyon ekiplerince (üretim operatörleri, ekip liderleri vb.) bilinmesi - Farklı vardiyalar arasında iletişimin sağlanması (ör. vardiya defteri) | O29: OK | Q29: =IF(P29="","",IF('Aksiyon Planı'!$N29="",P29,'Aksiyon Planı'!$N29)) | R29: Tesis tek vardiya çalışmakta ve geçmişinde dış müşteri şikâyeti bulunmamaktadır. Standart müdahale ve eskalasyon kuralları üretim iş istasyonlarında erişilebilir ve görünür durumdadır. Üretim ekiplerinin sınırlama eşiklerini bildiği doğrulanmıştır. İş günleri arasındaki operasyon sürekliliği, açık konuları ve teknik sorunları izleyen resmî günlük üretim kayıt defteriyle sağlanmaktadır. | W29: X | X29: X | Y29: X | AB29: X | AC29: X | AD29: X | AE29: X | AI29: X
G30: X | K30: X | L30: FR23 | M30: En kritik sorunlar hızlı müdahale panosunda belirlenmekte ve takip edilmektedir. | N30: - Sorunların hızlı müdahale veya hat QRQC panosunda takip edildiğini kontrol edin. - Tüm sorunların durum bilgisi bulunmalıdır. - Sorunlara ilişkin zaman planı kontrol altında olmalıdır. | O30: OK | Q30: =IF(P30="","",IF('Aksiyon Planı'!$N30="",P30,'Aksiyon Planı'!$N30)) | R30: Kritik kalite ve operasyon sorunlarını takip edip çözmek için üretim sahasında resmî Hızlı Müdahale / QRQC panosu kullanılmaktadır. Başlıca iç uygunsuzluklar, hurda Pareto nedenleri ve müşteri sorunları açık problem tanımlarıyla görsel olarak kaydedilmektedir. Her soruna bir sorumlu, aksiyon durumu (Açık, Devam Ediyor, Kapalı) ve kesin zaman hedefleri atanmaktadır. Günlük kısa değerlendirme toplantıları, aksiyonların zamanında yürütülmesini ve kapanış öncesi sınırlama etkinliğinin doğrulanmasını sağlamaktadır. | W30: X | X30: X | Y30: X | AD30: X | AE30: X | AI30: X
A31: FR3 | B31: Problem Çözme | G31: X | L31: FR31 | M31: Tüm iç ve dış sorunlara uygulanan, tanımlı ve standartlaştırılmış bir problem çözme yöntemi bulunmaktadır. | N31: Kontrol edin: - En son iç/dış sorun için aynı yöntemin kullanılması - Yöntemin 8D adımlarını izlemesi: Problem tanımı / Sınırlama / Hata kaydı / Kök nedenlerin belirlenmesi / Düzeltici aksiyon planı / Etkinlik kontrolü / Öğrenilen dersler / Benzer alanlara yaygınlaştırma - Tedarikçinin yöntemi doğru kullanması (ör. gerekli tüm adımları tamamlaması) | O31: OK | Q31: =IF(P31="","",IF('Aksiyon Planı'!$N31="",P31,'Aksiyon Planı'!$N31)) | R31: Müşteri şikâyeti sıfır olduğundan dış müşteri için 8D gerekmemiş olsa da tanımlı ve standart bir 8D problem çözme prosedürü tamamen oluşturulmuş, iç uygunsuzluklara ve kritik hurda eğilimlerine uygulanmaktadır. Yöntem, sınırlama ve kök neden analizinden etkinlik doğrulamasına ve benzer alanlara yaygınlaştırmaya kadar standart 8D aşamalarını izlemektedir. Tamamlanan iç 8D çalışmalarının tüm adımlarındaki uygunluğu doğrulamak için sürekli iç denetimler yapılmaktadır. | W31: X | X31: X | Y31: X | AB31: X | AC31: X | AD31: X | AE31: X | AI31: X
G32: X | L32: FR32 | M32: Kök neden belirleme, standart araçlar ve yöntemlerle desteklenmektedir. Bunlar, her sorunun en derin kök nedenlerini (oluşum, tespit ve sistemsel/öngörü) bulmak için kullanılmaktadır. | N32: Kontrol edin: - En az ISHIKAWA ve 5 NEDEN araçlarının kullanılması - Şüpheli tüm nedenlerin nihai kök nedene kadar incelenmesi: Ishikawa diyagramındaki her dalın oluşum ve tespit eksenlerinde tamamlanması, seçilmeyen nedenlerin gerekçelendirilmesi; seçilen nedenlerden 5 Neden aracılığıyla tüm olası kök nedenlerin belirlenmesi - Standart formun doğru doldurulması | O32: OK | Q32: =IF(P32="","",IF('Aksiyon Planı'!$N32="",P32,'Aksiyon Planı'!$N32)) | R32: Standart kök neden analizi araçları tanımlanmış ve hazırdır; iç incelemelere sistematik olarak uygulanmaktadır. Yapılandırılmış Ishikawa diyagramları ve iki eksenli 5 Neden analizleri (hem oluşum hem tespit hata türlerini kapsayan) standart inceleme şablonuna dahil edilmiştir. Ishikawa diyagramında seçilmeyen nedenler değerlendirilmekte ve belgelenmiş doğrulama verileriyle desteklenmektedir. Kök neden analizinin derinliğini korumak için fonksiyonlar arası rehberlik düzenli olarak sürdürülmektedir. | W32: X | X32: X | Y32: X | AB32: X | AC32: X | AD32: X | AE32: X | AI32: X
G33: X | L33: FR33 | M33: Benzer alanlara yaygınlaştırma / tekrarın önlenmesi standart araç ve yöntemlerle desteklenmektedir. | N33: Kontrol edin: - Kök nedenler ve ilgili düzeltici aksiyonlar benzer alanlara yaygınlaştırılmış ve öğrenilen ders olarak belgelenmiş mi? - PFMEA, Kontrol Planı / PIS vb. dokümanlar güncellenmiş mi? - Tekrar durumunda ilk problem çözme çalışması, neden başarısız olduğunu belirlemek için yeniden analiz ediliyor mu? | O33: OK | Q33: =IF(P33="","",IF('Aksiyon Planı'!$N33="",P33,'Aksiyon Planı'!$N33)) | R33: İç uygunsuzluklardan doğan düzeltici aksiyonların benzer cam işleme hatlarına ve ürün çeşitlerine aktarılmasını sağlamak için resmî bir yaygınlaştırma ve öğrenilen dersler yöntemi oluşturulmuştur. Prosedür, aksiyon kapanışında PFMEA'ların, Kontrol Planlarının ve kontrol standartlarının (PIS) zorunlu revizyon incelemesini gerektirir. Hata tekrarı durumunda önceki problem çözme analizlerini sistematik yeniden değerlendirecek standart protokoller tanımlanmıştır. | W33: X | X33: X | Y33: X | AC33: X | AD33: X | AE33: X | AI33: X
A34: Parça ve Proses Kontrolü | W34: 1 | Y34: 1 | AI34: X
